Workbook
Name Excel_BuiltIn__FilterDatabase_1: NA()

Sheet PLANTILLA VESP
A1: MATRICULA | B1: PLAZA | C1: NOMBRE | D1: PUESTO | E1: TUR | F1: DESCRIPCION | G1: A | H1: M | I1: D | J1: DESC | K1: TP | L1: SERVICIO
A2: 9988181 | B2: 38602 | C2: SANTAMARIA HERNANDEZ MIGUEL | D2: ENFERMERA GENERAL 80 | E2: VESP | F2: DEPARTAMENTO DE ENFERMERIA | G2: 32 | H2: 0 | I2: 10 | J2: S-D | K2: OPERATIVA BASE | L2: QX
A3: 98364380 | B3: 38234 | C3: GARCIA CRUZ CLAUDIA AIDA | D3: ENFERMERA ESPECIALISTA 80 EEQX | E3: VESP | F3: DEPARTAMENTO DE ENFERMERIA | J3: M-M | K3: OPERATIVA BASE | L3: QX
A4: 95155237 | B4: 38570 | C4: FLORES CASTRO KARLA ARLET (02) | D4: ENFERMERA GENERAL 80 | E4: VESP | F4: DEPARTAMENTO DE ENFERMERIA | G4: 0 | H4: 0 | I4: 0 | J4: J-V | K4: OPERATIVA BASE
A5: 95155398 | B5: 38795 | C5: BAUTISTA GARCIA CARLOS ALBERTO (02) | D5: ENFERMERA GENERAL 80 | E5: VESP | F5: DEPARTAMENTO DE ENFERMERIA | G5: 0 | H5: 0 | I5: 0 | J5: M-M | K5: CUBRE VACACIONES BASE
A6: 95155360 | B6: 38553 | C6: ROLDAN ROMERO JUAN PABLO | D6: ENFERMERA GENERAL 80 | E6: VESP | F6: DEPARTAMENTO DE ENFERMERIA | G6: 0 | H6: 0 | I6: 0 | J6: M-J | K6: OPERATIVA BASE | L6: CX GRAL
A7: 96155358 | B7: 70911 | C7: GAMEZ RAMIREZ OSCAR GIOVANNI | D7: CAMILLERO EN UNIDADES HOSPITALARIAS 80 | E7: VESP | F7: DEPARTAMENTO DE ENFERMERIA | G7: 3 | H7: 10 | I7: 9 | J7: M-M | K7: OPERATIVA BASE
A8: 95153562 | B8: 38327 | C8: VENEGAS SANTA OLAYA NAYELI ABIGAIL (02) | D8: AUX DE ENFERMERIA GRAL 80 | E8: VESP | F8: DEPARTAMENTO DE ENFERMERIA | G8: 0 | H8: 6 | I8: 12 | J8: D-L | K8: OPERATIVA BASE | L8: CX GRAL | M8: RESICION 16.SEP.2024
A9: 97155816 | B9: 37870 | C9: ORTEGA SANCHEZ ABEL GERARDO | D9: CAMILLERO EN UNIDADES HOSPITALARIAS 80 | E9: VESP | F9: DEPARTAMENTO DE ENFERMERIA | G9: 8 | H9: 10 | I9: 1 | J9: D-L | K9: OPERATIVA BASE
A10: 8713197 | B10: 38794 | C10: RUGERIO/ROJAS/MARIA DE LOURDES | D10: ENFERMERA GENERAL 80 | E10: VESP | F10: DEPARTAMENTO DE ENFERMERIA | G10: 28 | H10: 16 | I10: 14 | J10: D-L | K10: CUBRE VACACIONES BASE | L10: CE
A11: 97361428 | B11: 38322 | C11: ESPINA LOPEZ GUILLERMINA | D11: AUX DE ENFERMERIA GRAL 80 | E11: VESP | F11: DEPARTAMENTO DE ENFERMERIA | G11: 8 | H11: 4 | I11: 8 | J11: J-V | K11: OPERATIVA BASE | L11: UTQ
A12: 96153073 | B12: 38581 | C12: ELIZALDE GUARNEROS ESTEFANIA | D12: ENFERMERA GENERAL 80 | E12: VESP | F12: DEPARTAMENTO DE ENFERMERIA | G12: 3 | H12: 18 | I12: 12 | J12: M-J | K12: OPERATIVA BASE | L12: UTQ
A13: 11653183 | B13: 38399 | C13: RAMIREZ/CRUZ/PAULINA | D13: AUX DE ENFERMERIA GRAL 80 | E13: VESP | F13: DEPARTAMENTO DE ENFERMERIA | G13: 26 | H13: 15 | I13: 9 | J13: S-D | K13: CUBRE DESCANSOS BASE | L13: CE
A14: 11653329 | B14: 38302 | C14: REYES FLORES LUIS ALBERTO | D14: AUX DE ENFERMERIA GRAL 80 | E14: VESP | F14: DEPARTAMENTO DE ENFERMERIA | G14: 25 | H14: 6 | I14: 6 | J14: S-D | K14: OPERATIVA BASE | L14: RX
A15: 11359706 | B15: 38525 | C15: HERNANDEZ/MENDOZA/AMALIA | D15: ENFERMERA GENERAL CLINICA 80 | E15: VESP | F15: DEPARTAMENTO DE ENFERMERIA | G15: 25 | H15: 8 | I15: 0 | J15: S-D | K15: OPERATIVA BASE | L15: ENDOSCOPIA
A16: 11769491 | B16: 38167 | C16: ISLAS/URBINA/MARCO ANTONIO | D16: ENFERMERA JEFE DE PISO 80 | E16: VESP | F16: DEPARTAMENTO DE ENFERMERIA | G16: 25 | H16: 8 | I16: 12 | J16: S-D | K16: OPERATIVA BASE | L16: UTQ
A17: 11767359 | B17: 38164 | C17: LOPEZ/CHAVEZ/NORMA ELENA | D17: ENFERMERA JEFE DE PISO 80 | E17: VESP | F17: DEPARTAMENTO DE ENFERMERIA | G17: 25 | H17: 23 | I17: 10 | J17: S-D | K17: OPERATIVA BASE | L17: 0
A18: 11764562 | B18: 38520 | C18: RODRIGUEZ/ROQUE/CELERINA | D18: AUX DE ENFERMERIA GRAL 80 | E18: VESP | F18: DEPARTAMENTO DE ENFERMERIA | G18: 24 | H18: 6 | I18: 6 | J18: S-D | K18: OPERATIVA BASE | L18: UCIA
A19: 11776838 | B19: 38818 | C19: HERNANDEZ MEJIA LETICIA | D19: ENF ESPEC SALUD PUBL 80 EPH | E19: VESP | F19: DEPARTAMENTO DE ENFERMERIA | G19: 24 | H19: 14 | I19: 11 | J19: S-D | K19: OPERATIVA BASE | L19: EPH
A20: 11759658 | B20: 38212 | C20: AVILES CRUZ LOURDES | D20: ENFERMERA ESPECIALISTA 80 EEI | E20: VESP | F20: DEPARTAMENTO DE ENFERMERIA | G20: 24 | H20: 2 | I20: 7 | J20: D-L | K20: CUBRE DESCANSOS BASE | L20: UCIA
A21: 11770813 | B21: 38188 | C21: ESQUIVEL/RUBIO/MARIA TERESA | D21: ENFERMERA ESPECIALISTA 80 EEP | E21: VESP | F21: DEPARTAMENTO DE ENFERMERIA | G21: 24 | H21: 0 | I21: 10 | J21: S-D | K21: CUBRE DESCANSOS BASE | L21: UCIN
A22: 11770678 | B22: 38572 | C22: CONTRERAS/CONTRERAS/ROSA MARIA | D22: ENFERMERA GENERAL 80 | E22: VESP | F22: DEPARTAMENTO DE ENFERMERIA | G22: 24 | H22: 7 | I22: 12 | J22: S-D | K22: OPERATIVA BASE | L22: CE
A23: 99350354 | B23: 38319 | C23: GARCIA PACHECO DAVID | D23: AUX DE ENFERMERIA GRAL 80 | E23: VESP | F23: DEPARTAMENTO DE ENFERMERIA | G23: 23 | H23: 13 | I23: 0 | J23: S-D | K23: OPERATIVA BASE | L23: CE
A24: 99370268 | B24: 38340 | C24: JIMENEZ TORIZ RAUL | D24: AUX DE ENFERMERIA GRAL 80 | E24: VESP | F24: DEPARTAMENTO DE ENFERMERIA | G24: 23 | H24: 21 | I24: 13 | J24: S-D | K24: OPERATIVA BASE | L24: CE | N24: Elba
A25: 11777575 | B25: 38526 | C25: CHORE&O/CRUZ/JUANA | D25: ENFERMERA GENERAL 80 | E25: VESP | F25: DEPARTAMENTO DE ENFERMERIA | G25: 23 | H25: 18 | I25: 12 | J25: S-D | K25: OPERATIVA BASE | L25: CE
A26: 11182466 | B26: 38124 | C26: BRIBIESCA/RAYA/BLANCA ESTELA | D26: N41 SUBJ ENF UM A 80 | E26: VESP | F26: DEPARTAMENTO DE ENFERMERIA | G26: 23 | H26: 14 | I26: 3 | J26: S-D | K26: CONFIANZA
A27: 99350836 | B27: 38316 | C27: DE LUCIO/RUIZ/JUAN GABRIEL | D27: AUX DE ENFERMERIA GRAL 80 | E27: VESP | F27: DEPARTAMENTO DE ENFERMERIA | G27: 22 | H27: 1 | I27: 10 | J27: S-D | K27: OPERATIVA BASE | L27: CE
A28: 11486775 | B28: 38333 | C28: GARCIA/GALICIA/ROSALBA CAROLINA | D28: AUX DE ENFERMERIA GRAL 80 | E28: VESP | F28: DEPARTAMENTO DE ENFERMERIA | G28: 22 | H28: 19 | I28: 13 | J28: S-D | K28: OPERATIVA BASE | L28: CE
A29: 99371174 | B29: 38746 | C29: ESTRADA/BOLA&OS/RAUL | D29: ENFERMERA GENERAL CLINICA 80 | E29: VESP | F29: DEPARTAMENTO DE ENFERMERIA | G29: 22 | H29: 21 | I29: 13 | J29: S-D | K29: CUBRE DESCANSOS BASE | L29: CE
A30: 99152413 | B30: 38336 | C30: RAMIREZ GUERRERO CARLOS | D30: AUX DE ENFERMERIA GRAL 80 | E30: VESP | F30: DEPARTAMENTO DE ENFERMERIA | G30: 21 | H30: 4 | I30: 5 | J30: S-D | K30: OPERATIVA BASE | L30: UPP
A31: 99160152 | B31: 36945 | C31: JIMENEZ DOMINGUEZ JULIO CESAR | D31: CAMILLERO EN UNIDADES HOSPITALARIAS 80 | E31: VESP | F31: DEPARTAMENTO DE ENFERMERIA | G31: 21 | H31: 22 | I31: 8 | J31: S-D | K31: CUBRE DESCANSOS BASE | L31: CUH
A32: 99350981 | B32: 38240 | C32: HERNANDEZ/SEVILLA/ALMA KARINA | D32: ENFERMERA ESPECIALISTA 80 EEQX | E32: VESP | F32: DEPARTAMENTO DE ENFERMERIA | G32: 21 | H32: 14 | I32: 9 | J32: S-D | K32: CUBRE DESCANSOS BASE | L32: QX
A33: 99381666 | B33: 38542 | C33: MARTINEZ/SANDOVAL/JOSE LUIS | D33: ENFERMERA GENERAL 80 | E33: VESP | F33: DEPARTAMENTO DE ENFERMERIA | G33: 21 | H33: 23 | I33: 4 | J33: S-D | K33: OPERATIVA BASE | L33: CE
A34: 99381684 | B34: 38162 | C34: GAMERO GARCIA YOLANDA MARIEL | D34: ENFERMERA JEFE DE PISO 80 | E34: VESP | F34: DEPARTAMENTO DE ENFERMERIA | G34: 21 | H34: 15 | I34: 13 | J34: S-D | K34: OPERATIVA BASE | L34: 0
A35: 99370975 | B35: 38168 | C35: MARTINEZ/CALIXTO/CAROLINA | D35: ENFERMERA JEFE DE PISO 80 | E35: VESP | F35: DEPARTAMENTO DE ENFERMERIA | G35: 21 | H35: 12 | I35: 9 | J35: S-D | K35: OPERATIVA BASE | L35: 0
A36: 99361644 | B36: 38112 | C36: CARPINTERO/BIXANO/MARIA DOLORES | D36: N41 SUBJ ENF UM A 80 | E36: VESP | F36: DEPARTAMENTO DE ENFERMERIA | G36: 21 | H36: 19 | I36: 5 | J36: D-L | K36: CONFIANZA
A37: 12145777 | B37: 38757 | C37: ROJAS/DAVALOS/ERIC | D37: ENFERMERA GENERAL 80 | E37: VESP | F37: DEPARTAMENTO DE ENFERMERIA | G37: 20 | H37: 4 | I37: 0 | J37: S-D | K37: CUBRE DESCANSOS BASE | L37: URG
A38: 99363089 | B38: 38587 | C38: RUIZ HERNANDEZ ANGELICA | D38: ENFERMERA GENERAL 80 | E38: VESP | F38: DEPARTAMENTO DE ENFERMERIA | G38: 20 | H38: 14 | I38: 0 | J38: S-D | K38: OPERATIVA BASE | L38: CG
A39: 11776501 | B39: 38163 | C39: VAZQUEZ DEL MERCADO/ZUNIGA/VIOLETA | D39: ENFERMERA JEFE DE PISO 80 | E39: VESP | F39: DEPARTAMENTO DE ENFERMERIA | G39: 20 | H39: 22 | I39: 14 | J39: S-D | K39: OPERATIVA BASE | L39: 0
A40: 99154468 | B40: 38793 | C40: FUENTES CASTILLO BLANCA CAROLINA | D40: ENFERMERA GENERAL 80 | E40: VESP | F40: DEPARTAMENTO DE ENFERMERIA | G40: 19 | H40: 16 | I40: 3 | J40: S-D | K40: CUBRE VACACIONES BASE | L40: CE
...

Sheet Hoja1
A1: INSTITUTO MEXICANO DEL SEGURO SOCIAL
A2: DIRECCION DE PRESTACIONES MEDICAS COORDINACION DE ATENCION INTREGRAL EN SEGUNDO NIVEL
A3: DEPARTAMENTO DE ENFERMERIA
A4: HOSPITAL GENERAL REGIONAL N0. 200
A5: TECAMAC
A7: NOMBRE: | B7: ROJANO VERDI JOSE ARTURO | J7: CAT: | L7: CAMILLERO DE UNIDADES HOSPITALARIAS | S7: MATRICULA: | V7: 96155509 | Y7: CC | AB7: DESCANSO: | AE7: JORNADA | AH7: No PLAZA | AK7: =VLOOKUP(V7,'PLANTILLA VESP'!A1:L298,2,FALSE) -> #N/A
A9: PISO | D9: SERVICIO | J9: F. INGRESO | P9: TIPO DE PLAZA | T9: =VLOOKUP(V7,'PLANTILLA VESP'!A1:L298,11,FALSE) -> #N/A | Y9: ROL.VAC | AD9: MARCA DE INC | AI9: AÑO: | AK9: 2025
A10: MES/DIA
A11: ENERO | B11: L | C11: M | D11: M-1 | E11: J-2 | F11: V-3 | G11: S-4 | H11: D-5 | I11: L-6 | J11: M-7 | K11: M-8 | L11: J-9 | M11: V-10 | N11: S-11 | O11: D-12 | P11: L-13 | Q11: M-14 | R11: M-15 | S11: J-16 | T11: V-17 | U11: S-18 | V11: D-19 | W11: L-20 | X11: M-21 | Y11: M-22 | Z11: J-23 | AA11: V-24 | AB11: S-25 | AC11: D-26 | AD11: L-27 | AE11: M-28 | AF11: M-29 | AG11: J-30 | AH11: V-31 | AI11: S | AJ11: D | AK11: L | AL11: M
A13: FEBRERO | B13: L | C13: M | D13: M | E13: J | F13: V | G13: S-1 | H13: D-2 | I13: L-3 | J13: M-4 | K13: M-5 | L13: J-6 | M13: V-7 | N13: S-8 | O13: D-9 | P13: L-10 | Q13: M-11 | R13: M-12 | S13: J-13 | T13: V-14 | U13: S-15 | V13: D-16 | W13: L-17 | X13: M-18 | Y13: M-19 | Z13: J-20 | AA13: V-21 | AB13: S-22 | AC13: D-23 | AD13: L-24 | AE13: M-25 | AF13: M-26 | AG13: J-27 | AH13: V- 28 | AI13: S | AJ13: D | AK13: L | AL13: M
A15: MARZO | B15: L | C15: M | D15: M | E15: J | F15: V | G15: S-1 | H15: D-2 | I15: L-3 | J15: M-4 | K15: M-5 | L15: J-6 | M15: V-7 | N15: S-8 | O15: D-9 | P15: L-10 | Q15: M-11 | R15: M-12 | S15: J-13 | T15: V-14 | U15: S-15 | V15: D-16 | W15: L-17 | X15: M-18 | Y15: M-19 | Z15: J-20 | AA15: V-21 | AB15: S-22 | AC15: D-23 | AD15: L-24 | AE15: M-25 | AF15: M-26 | AG15: J-27 | AH15: V- 28 | AI15: S-29 | AJ15: D-30 | AK15: L-31 | AL15: M
A17: ABRIL | B17: L | C17: M-1 | D17: M-2 | E17: J-3 | F17: V-4 | G17: S-5 | H17: D-6 | I17: L-7 | J17: M-8 | K17: M-9 | L17: J-10 | M17: V-11 | N17: S-12 | O17: D-13 | P17: L-14 | Q17: M-15 | R17: M-16 | S17: J-17 | T17: V-18 | U17: S-19 | V17: D-20 | W17: L-21 | X17: M-22 | Y17: M-23 | Z17: J-24 | AA17: V-25 | AB17: S-26 | AC17: D-27 | AD17: L-28 | AE17: M-29 | AF17: M-30 | AG17: J | AH17: V | AI17: S | AJ17: D | AK17: L | AL17: M
A19: MAYO | B19: | | C19: M | D19: M | E19: J-1 | F19: V-2 | G19: S-3 | H19: D-4 | I19: L-5 | J19: M-6 | K19: M-7 | L19: J-8 | M19: V-9 | N19: S-10 | O19: D-11 | P19: L-12 | Q19: M-13 | R19: M-14 | S19: J-15 | T19: V-16 | U19: S-17 | V19: D-18 | W19: L-19 | X19: M-20 | Y19: M-21 | Z19: J-22 | AA19: V-23 | AB19: S-24 | AC19: D-25 | AD19: L-26 | AE19: M-27 | AF19: M-28 | AG19: J-29 | AH19: V-30 | AI19: S-31 | AJ19: D | AK19: L | AL19: M
A21: JUNIO | B21: L | C21: M | D21: M | E21: J | F21: V | G21: S | H21: D-1 | I21: L-2 | J21: M-3 | K21: M-4 | L21: J-5 | M21: V-6 | N21: S-7 | O21: D-8 | P21: L-9 | Q21: M-10 | R21: M-11 | S21: J-12 | T21: V-13 | U21: S-14 | V21: D-15 | W21: L-16 | X21: M-17 | Y21: M-18 | Z21: J-19 | AA21: V-20 | AB21: S-21 | AC21: D-22 | AD21: L-23 | AE21: M-24 | AF21: M-25 | AG21: J-26 | AH21: V- 27 | AI21: S-28 | AJ21: D-29 | AK21: L-30 | AL21: M
A23: JULIO | B23: L | C23: M-1 | D23: M-2 | E23: J-3 | F23: V-4 | G23: S-5 | H23: D-6 | I23: L-7 | J23: M-8 | K23: M-9 | L23: J-10 | M23: V-11 | N23: S-12 | O23: D-13 | P23: L-14 | Q23: M-15 | R23: M-16 | S23: J-17 | T23: V-18 | U23: S-19 | V23: D-20 | W23: L-21 | X23: M-22 | Y23: M-23 | Z23: J-24 | AA23: V-25 | AB23: S-26 | AC23: D-27 | AD23: L-28 | AE23: M-29 | AF23: M-30 | AG23: J-31 | AH23: V | AI23: S | AJ23: D | AK23: L | AL23: M
A25: AGOSTO | B25: L | C25: M | D25: M | E25: J | F25: V-1 | G25: S-2 | H25: D-3 | I25: L-4 | J25: M-5 | K25: M-6 | L25: J-7 | M25: V-8 | N25: S-9 | O25: D-10 | P25: L-11 | Q25: M-12 | R25: M-13 | S25: J-14 | T25: V-15 | U25: S-16 | V25: D-17 | W25: L-18 | X25: M-19 | Y25: M-20 | Z25: J-21 | AA25: V-22 | AB25: S-23 | AC25: D-24 | AD25: L-25 | AE25: M-26 | AF25: M-27 | AG25: J-28 | AH25: V-29 | AI25: S-30 | AJ25: D-31 | AK25: L | AL25: M
A27: SEPTIEMBRE | B27: L-1 | C27: M-2 | D27: M-3 | E27: J-4 | F27: V-5 | G27: S-6 | H27: D-7 | I27: L-8 | J27: M-9 | K27: M-10 | L27: J-11 | M27: V-12 | N27: S-13 | O27: D-14 | P27: L-15 | Q27: M-16 | R27: M-17 | S27: J-18 | T27: V-19 | U27: S-20 | V27: D-21 | W27: L-22 | X27: M-23 | Y27: M-24 | Z27: J-25 | AA27: V- 26 | AB27: S-27 | AC27: D-28 | AD27: L-29 | AE27: M-30 | AF27: M | AG27: J | AH27: V | AI27: S | AJ27: D | AK27: L | AL27: M
A29: OCTUBRE | B29: L | C29: M | D29: M-1 | E29: J-2 | F29: V-3 | G29: S-4 | H29: D-5 | I29: L-6 | J29: M-7 | K29: M-8 | L29: J-9 | M29: V-10 | N29: S-11 | O29: D-12 | P29: L-13 | Q29: M-14 | R29: M-15 | S29: J-16 | T29: V-17 | U29: S-18 | V29: D-19 | W29: L-20 | X29: M-21 | Y29: M-22 | Z29: J-23 | AA29: V-24 | AB29: S-25 | AC29: D-26 | AD29: L-27 | AE29: M-28 | AF29: M-29 | AG29: J-30 | AH29: V-31 | AI29: S | AJ29: D | AK29: L | AL29: M
A31: NOVIEMBRE | B31: L | C31: M | D31: M | E31: J | F31: V | G31: S-1 | H31: D-2 | I31: L-3 | J31: M-4 | K31: M-5 | L31: J-6 | M31: V-7 | N31: S-8 | O31: D-9 | P31: L-10 | Q31: M-11 | R31: M-12 | S31: J-13 | T31: V-14 | U31: S-15 | V31: D-16 | W31: L-17 | X31: M-18 | Y31: M-19 | Z31: J-20 | AA31: V-21 | AB31: S-22 | AC31: D-23 | AD31: L-24 | AE31: M-25 | AF31: M-26 | AG31: J-27 | AH31: V-28 | AI31: S-29 | AJ31: D-30 | AK31: L | AL31: M
A33: DICIEMBRE | B33: L-1 | C33: M-2 | D33: M-3 | E33: J-4 | F33: V-5 | G33: S-6 | H33: D-7 | I33: L-8 | J33: M-9 | K33: M-10 | L33: J-11 | M33: V-12 | N33: S-13 | O33: D-14 | P33: L-15 | Q33: M-16 | R33: M-17 | S33: J-18 | T33: V-19 | U33: S-20 | V33: D-21 | W33: L-22 | X33: M-23 | Y33: M-24 | Z33: J-25 | AA33: V- 26 | AB33: S-27 | AC33: D-28 | AD33: L-29 | AE33: M-30 | AF33: M-31 | AG33: J | AH33: V | AI33: S | AJ33: D | AK33: L | AL33: M
F37: LIC. SANDRA CASTILLO HERNÁNDEZ | AA37: MTRA. AIDEE CASTILLO SANDOVAL
F39: JEFE DE ENFERMERAS | AA39: SUBJEFE DE ENFERMERAS

Sheet Config
A1: Descanso | B1: Dia 1 | C1: Dia 2 | E1: Dias feriados
A2: L-M | B2: 1 | C2: 2 | E2: 45658
A3: M-M | B3: 2 | C3: 3 | E3: 45690
A4: M-J | B4: 3 | C4: 4 | E4: 45732
A5: J-V | B5: 4 | C5: 5 | E5: 45749
A6: V-S | B6: 5 | C6: 6 | E6: 45750
A7: S-D | B7: 6 | C7: 7 | E7: 45751
A8: D-L | B8: 7 | C8: 1 | E8: 45778
E9: 45787
E10: 45915
E11: 45916
E12: 45977
E13: 46016

Sheet BLANCO
A1: INSTITUTO MEXICANO DEL SEGURO SOCIAL
A2: DIRECCION DE PRESTACIONES MEDICAS COORDINACION DE ATENCION INTREGRAL EN SEGUNDO NIVEL
A3: DEPARTAMENTO DE ENFERMERIA
A4: HOSPITAL GENERAL REGIONAL N0. 200
A5: TECAMAC
B7: =VLOOKUP(V7,#REF!,3,0) -> #REF! | N7: CAT: | O7: 99385680 | S7: MATRICULA: | Y7: CC | AB7: DESCANSO: | AE7: =VLOOKUP(V7,#REF!,11,0) -> #REF! | AH7: No PLAZA | AK7: =VLOOKUP(V7,#REF!,2,0) -> #REF!
A9: PISO | D9: SERVICIO | J9: F. INGRESO | P9: TIPO DE PLAZA | U9: =VLOOKUP(V7,#REF!,12,0) -> #REF! | Y9: ROL.VAC | AD9: MARCA DE INC | AI9: AÑO:
A10: MES/DIA
A11: ENERO | B11: L | C11: M | D11: M | E11: J | F11: V-1 | G11: S-2 | H11: D-3 | I11: L-4 | J11: M-5 | K11: M-6 | L11: J-7 | M11: V-8 | N11: S-9 | O11: D-10 | P11: L-11 | Q11: M-12 | R11: M-13 | S11: J-14 | T11: V-15 | U11: S-16 | V11: D-17 | W11: L-18 | X11: M-19 | Y11: M-20 | Z11: J-21 | AA11: V-22 | AB11: S-23 | AC11: D-24 | AD11: L-25 | AE11: M-26 | AF11: M-27 | AG11: J-28 | AH11: V- 29 | AI11: S-30 | AJ11: D-31 | AK11: L | AL11: M
A13: FEBRERO | B13: L-1 | C13: M-2 | D13: M-3 | E13: J-4 | F13: V-5 | G13: S-6 | H13: D-7 | I13: L-8 | J13: M-9 | K13: M-10 | L13: J-11 | M13: V-12 | N13: S-13 | O13: D-14 | P13: L-15 | Q13: M-16 | R13: M-17 | S13: J-18 | T13: V-19 | U13: S-20 | V13: D-21 | W13: L-22 | X13: M-23 | Y13: M-24 | Z13: J-25 | AA13: V-26 | AB13: S-27 | AC13: D-28 | AD13: L | AE13: M | AF13: M | AG13: J | AH13: V | AI13: S | AJ13: D | AK13: L | AL13: M
A15: MARZO | B15: L-1 | C15: M-2 | D15: M-3 | E15: J-4 | F15: V-5 | G15: S-6 | H15: D-7 | I15: L-8 | J15: M-9 | K15: M-10 | L15: J-11 | M15: V-12 | N15: S-13 | O15: D-14 | P15: L-15 | Q15: M-16 | R15: M-17 | S15: J-18 | T15: V-19 | U15: S-20 | V15: D-21 | W15: L-22 | X15: M-23 | Y15: M-24 | Z15: J-25 | AA15: V-26 | AB15: S-27 | AC15: D-28 | AD15: L-29 | AE15: M-30 | AF15: M-31 | AG15: J | AH15: V | AI15: S | AJ15: D | AK15: L | AL15: M
A17: ABRIL | B17: L | C17: M | D17: M | E17: J-1 | F17: V-2 | G17: S-3 | H17: D-4 | I17: L-5 | J17: M-6 | K17: M-7 | L17: J-8 | M17: V-9 | N17: S-10 | O17: D-11 | P17: L-12 | Q17: M-13 | R17: M-14 | S17: J-15 | T17: V-16 | U17: S-17 | V17: D-18 | W17: L-19 | X17: M-20 | Y17: M-21 | Z17: J-22 | AA17: V-23 | AB17: S-24 | AC17: D-25 | AD17: L-26 | AE17: M-27 | AF17: M-28 | AG17: J-29 | AH17: V-30 | AI17: S | AJ17: D | AK17: L | AL17: M
A19: MAYO | B19: L | C19: M | D19: M | E19: J | F19: V | G19: S-1 | H19: D-2 | I19: L-3 | J19: M-4 | K19: M-5 | L19: J-6 | M19: V-7 | N19: S-8 | O19: D-9 | P19: L-10 | Q19: M-11 | R19: M-12 | S19: J-13 | T19: V-14 | U19: S-15 | V19: D-16 | W19: L-17 | X19: M-18 | Y19: M-19 | Z19: J-20 | AA19: V-21 | AB19: S-22 | AC19: D-23 | AD19: L-24 | AE19: M-25 | AF19: M-26 | AG19: J-27 | AH19: V-28 | AI19: S-29 | AJ19: D-30 | AK19: L-31 | AL19: M
A21: JUNIO | B21: L | C21: M-1 | D21: M-2 | E21: J-3 | F21: V-4 | G21: S-5 | H21: D-6 | I21: L-7 | J21: M-8 | K21: M-9 | L21: J-10 | M21: V-11 | N21: S-12 | O21: D-13 | P21: L-14 | Q21: M-15 | R21: M-16 | S21: J-17 | T21: V-18 | U21: S-19 | V21: D-20 | W21: L-21 | X21: M-22 | Y21: M-23 | Z21: J-24 | AA21: V-25 | AB21: S-26 | AC21: D-27 | AD21: L-28 | AE21: M-29 | AF21: M-30 | AG21: J | AH21: V | AI21: S | AJ21: D | AK21: L | AL21: M
A23: JULIO | B23: L | C23: M | D23: M | E23: J-1 | F23: V-2 | G23: S-3 | H23: D-4 | I23: L-5 | J23: M-6 | K23: M-7 | L23: J-8 | M23: V-9 | N23: S-10 | O23: D-11 | P23: L-12 | Q23: M-13 | R23: M-14 | S23: J-15 | T23: V-16 | U23: S-17 | V23: D-18 | W23: L-19 | X23: M-20 | Y23: M-21 | Z23: J-22 | AA23: V-23 | AB23: S-24 | AC23: D-25 | AD23: L-26 | AE23: M-27 | AF23: M-28 | AG23: J-29 | AH23: V-30 | AI23: S-31 | AJ23: D | AK23: L | AL23: M
A25: AGOSTO | B25: L | C25: M | D25: M | E25: J | F25: V | G25: S | H25: D-1 | I25: L-2 | J25: M-3 | K25: M-4 | L25: J-5 | M25: V-6 | N25: S-7 | O25: D-8 | P25: L-9 | Q25: M-10 | R25: M-11 | S25: J-12 | T25: V-13 | U25: S-14 | V25: D-15 | W25: L-16 | X25: M-17 | Y25: M-18 | Z25: J-19 | AA25: V-20 | AB25: S-21 | AC25: D-22 | AD25: L-23 | AE25: M-24 | AF25: M-25 | AG25: J-26 | AH25: V-27 | AI25: S-28 | AJ25: D-29 | AK25: L-30 | AL25: M-31
A27: SEPTIEMBRE | B27: L | C27: M | D27: M-1 | E27: J-2 | F27: V-3 | G27: S-4 | H27: D-5 | I27: L-6 | J27: M-7 | K27: M-8 | L27: J-9 | M27: V-10 | N27: S-11 | O27: D-12 | P27: L-13 | Q27: M-14 | R27: M-15 | S27: J-16 | T27: V-17 | U27: S-18 | V27: D-19 | W27: L-20 | X27: M-21 | Y27: M-22 | Z27: J-23 | AA27: V-24 | AB27: S-25 | AC27: D-26 | AD27: L-27 | AE27: M-28 | AF27: M-29 | AG27: J-30 | AH27: V | AI27: S | AJ27: D | AK27: L | AL27: M
A29: OCTUBRE | B29: L | C29: M | D29: M | E29: J | F29: V-1 | G29: S-2 | H29: D-3 | I29: L-4 | J29: M-5 | K29: M-6 | L29: J-7 | M29: V-8 | N29: S-9 | O29: D-10 | P29: L-11 | Q29: M-12 | R29: M-13 | S29: J-14 | T29: V-15 | U29: S-16 | V29: D-17 | W29: L-18 | X29: M-19 | Y29: M-20 | Z29: J-21 | AA29: V-22 | AB29: S-23 | AC29: D-24 | AD29: L-25 | AE29: M-26 | AF29: M-27 | AG29: J-28 | AH29: V- 29 | AI29: S-30 | AJ29: D-31 | AK29: L | AL29: M
A31: NOVIEMBRE | B31: L-1 | C31: M-2 | D31: M-3 | E31: J-4 | F31: V-5 | G31: S-6 | H31: D-7 | I31: L-8 | J31: M-9 | K31: M-10 | L31: J-11 | M31: V-12 | N31: S-13 | O31: D-14 | P31: L-15 | Q31: M-16 | R31: M-17 | S31: J-18 | T31: V-19 | U31: S-20 | V31: D-21 | W31: L-22 | X31: M-23 | Y31: M-24 | Z31: J-25 | AA31: V-26 | AB31: S-27 | AC31: D-28 | AD31: L-29 | AE31: M-30 | AF31: M | AG31: J | AH31: V | AI31: S | AJ31: D | AK31: L | AL31: M
A33: DICIEMBRE | B33: L | C33: M | D33: M-1 | E33: J-2 | F33: V-3 | G33: S-4 | H33: D-5 | I33: L-6 | J33: M-7 | K33: M-8 | L33: J-9 | M33: V-10 | N33: S-11 | O33: D-12 | P33: L-13 | Q33: M-14 | R33: M-15 | S33: J-16 | T33: V-17 | U33: S-18 | V33: D-19 | W33: L-20 | X33: M-21 | Y33: M-22 | Z33: J-23 | AA33: V-24 | AB33: S-25 | AC33: D-26 | AD33: L-27 | AE33: M-28 | AF33: M-29 | AG33: J-30 | AH33: V-31 | AI33: S | AJ33: D | AK33: L | AL33: M
F37: LIC. JOSE ALBERTO MOCTEZUMA PAREDES | AA37: LIC. CLAUDIA GUADALUPE GONZALEZ SOLIS
F39: JEFE DE ENFERMERAS | AA39: SUBJEFE DE ENFERMERAS
A40: INSTITUTO MEXICANO DEL SEGURO SOCIAL
A41: DIRECCION DE PRESTACIONES MEDICAS COORDINACION DE ATENCION INTREGRAL EN SEGUNDO NIVEL
A42: DEPARTAMENTO DE ENFERMERIA
A43: HOSPITAL GENERAL REGIONAL N0. 200
A44: TECAMAC
B46: =VLOOKUP(V46,#REF!,3,0) -> #REF! | N46: CAT: | P46: =VLOOKUP(V46,#REF!,4,0) -> #REF! | S46: MATRICULA: | V46: 99385680 | Y46: CC | AB46: DESCANSO: | AE46: =VLOOKUP(V46,#REF!,11,0) -> #REF! | AH46: No PLAZA | AK46: =VLOOKUP(V46,#REF!,2,0) -> #REF!
A48: PISO | D48: SERVICIO | J48: F. INGRESO | P48: TIPO DE PLAZA | U48: =VLOOKUP(V46,#REF!,12,0) -> #REF! | Y48: ROL.VAC | AD48: MARCA DE INC | AJ48: AÑO: 2021
A49: MES/DIA
A50: ENERO | B50: L | C50: M | D50: M | E50: J | F50: V-1 | G50: S-2 | H50: D-3 | I50: L-4 | J50: M-5 | K50: M-6 | L50: J-7 | M50: V-8 | N50: S-9 | O50: D-10 | P50: L-11 | Q50: M-12 | R50: M-13 | S50: J-14 | T50: V-15 | U50: S-16 | V50: D-17 | W50: L-18 | X50: M-19 | Y50: M-20 | Z50: J-21 | AA50: V-22 | AB50: S-23 | AC50: D-24 | AD50: L-25 | AE50: M-26 | AF50: M-27 | AG50: J-28 | AH50: V- 29 | AI50: S-30 | AJ50: D-31 | AK50: L | AL50: M
A52: FEBRERO | B52: L-1 | C52: M-2 | D52: M-3 | E52: J-4 | F52: V-5 | G52: S-6 | H52: D-7 | I52: L-8 | J52: M-9 | K52: M-10 | L52: J-11 | M52: V-12 | N52: S-13 | O52: D-14 | P52: L-15 | Q52: M-16 | R52: M-17 | S52: J-18 | T52: V-19 | U52: S-20 | V52: D-21 | W52: L-22 | X52: M-23 | Y52: M-24 | Z52: J-25 | AA52: V-26 | AB52: S-27 | AC52: D-28 | AD52: L | AE52: M | AF52: M | AG52: J | AH52: V | AI52: S | AJ52: D | AK52: L | AL52: M
AI53: }
A54: MARZO | B54: L-1 | C54: M-2 | D54: M-3 | E54: J-4 | F54: V-5 | G54: S-6 | H54: D-7 | I54: L-8 | J54: M-9 | K54: M-10 | L54: J-11 | M54: V-12 | N54: S-13 | O54: D-14 | P54: L-15 | Q54: M-16 | R54: M-17 | S54: J-18 | T54: V-19 | U54: S-20 | V54: D-21 | W54: L-22 | X54: M-23 | Y54: M-24 | Z54: J-25 | AA54: V-26 | AB54: S-27 | AC54: D-28 | AD54: L-29 | AE54: M-30 | AF54: M-31 | AG54: J | AH54: V | AI54: S | AJ54: D | AK54: L | AL54: M
A56: ABRIL | B56: L | C56: M | D56: M | E56: J-1 | F56: V-2 | G56: S-3 | H56: D-4 | I56: L-5 | J56: M-6 | K56: M-7 | L56: J-8 | M56: V-9 | N56: S-10 | O56: D-11 | P56: L-12 | Q56: M-13 | R56: M-14 | S56: J-15 | T56: V-16 | U56: S-17 | V56: D-18 | W56: L-19 | X56: M-20 | Y56: M-21 | Z56: J-22 | AA56: V-23 | AB56: S-24 | AC56: D-25 | AD56: L-26 | AE56: M-27 | AF56: M-28 | AG56: J-29 | AH56: V-30 | AI56: S | AJ56: D | AK56: L | AL56: M
A58: MAYO | B58: L | C58: M | D58: M | E58: J | F58: V | G58: S-1 | H58: D-2 | I58: L-3 | J58: M-4 | K58: M-5 | L58: J-6 | M58: V-7 | N58: S-8 | O58: D-9 | P58: L-10 | Q58: M-11 | R58: M-12 | S58: J-13 | T58: V-14 | U58: S-15 | V58: D-16 | W58: L-17 | X58: M-18 | Y58: M-19 | Z58: J-20 | AA58: V-21 | AB58: S-22 | AC58: D-23 | AD58: L-24 | AE58: M-25 | AF58: M-26 | AG58: J-27 | AH58: V-28 | AI58: S-29 | AJ58: D-30 | AK58: L-31 | AL58: M
A60: JUNIO | B60: L | C60: M-1 | D60: M-2 | E60: J-3 | F60: V-4 | G60: S-5 | H60: D-6 | I60: L-7 | J60: M-8 | K60: M-9 | L60: J-10 | M60: V-11 | N60: S-12 | O60: D-13 | P60: L-14 | Q60: M-15 | R60: M-16 | S60: J-17 | T60: V-18 | U60: S-19 | V60: D-20 | W60: L-21 | X60: M-22 | Y60: M-23 | Z60: J-24 | AA60: V-25 | AB60: S-26 | AC60: D-27 | AD60: L-28 | AE60: M-29 | AF60: M-30 | AG60: J | AH60: V | AI60: S | AJ60: D | AK60: L | AL60: M
A62: JULIO | B62: L | C62: M | D62: M | E62: J-1 | F62: V-2 | G62: S-3 | H62: D-4 | I62: L-5 | J62: M-6 | K62: M-7 | L62: J-8 | M62: V-9 | N62: S-10 | O62: D-11 | P62: L-12 | Q62: M-13 | R62: M-14 | S62: J-15 | T62: V-16 | U62: S-17 | V62: D-18 | W62: L-19 | X62: M-20 | Y62: M-21 | Z62: J-22 | AA62: V-23 | AB62: S-24 | AC62: D-25 | AD62: L-26 | AE62: M-27 | AF62: M-28 | AG62: J-29 | AH62: V-30 | AI62: S-31 | AJ62: D | AK62: L | AL62: M
A64: AGOSTO | B64: L | C64: M | D64: M | E64: J | F64: V | G64: S | H64: D-1 | I64: L-2 | J64: M-3 | K64: M-4 | L64: J-5 | M64: V-6 | N64: S-7 | O64: D-8 | P64: L-9 | Q64: M-10 | R64: M-11 | S64: J-12 | T64: V-13 | U64: S-14 | V64: D-15 | W64: L-16 | X64: M-17 | Y64: M-18 | Z64: J-19 | AA64: V-20 | AB64: S-21 | AC64: D-22 | AD64: L-23 | AE64: M-24 | AF64: M-25 | AG64: J-26 | AH64: V-27 | AI64: S-28 | AJ64: D-29 | AK64: L-30 | AL64: M-31
A66: SEPTIEMBRE | B66: L | C66: M | D66: M-1 | E66: J-2 | F66: V-3 | G66: S-4 | H66: D-5 | I66: L-6 | J66: M-7 | K66: M-8 | L66: J-9 | M66: V-10 | N66: S-11 | O66: D-12 | P66: L-13 | Q66: M-14 | R66: M-15 | S66: J-16 | T66: V-17 | U66: S-18 | V66: D-19 | W66: L-20 | X66: M-21 | Y66: M-22 | Z66: J-23 | AA66: V-24 | AB66: S-25 | AC66: D-26 | AD66: L-27 | AE66: M-28 | AF66: M-29 | AG66: J-30 | AH66: V | AI66: S | AJ66: D | AK66: L | AL66: M
...

Sheet S-D
A1: INSTITUTO MEXICANO DEL SEGURO SOCIAL
A2: DIRECCION DE PRESTACIONES MEDICAS COORDINACION DE ATENCION INTREGRAL EN SEGUNDO NIVEL
A3: DEPARTAMENTO DE ENFERMERIA
A4: HOSPITAL GENERAL REGIONAL N0. 200
A5: TECAMAC
A7: NOMBRE: | B7: =VLOOKUP(V7,'PLANTILLA VESP'!A1:L312,3,FALSE) -> RODRIGUEZ RAMOS URIEL (02) | J7: CAT: | L7: =VLOOKUP(V7,'PLANTILLA VESP'!A1:L312,4,FALSE) -> CAMILLERO EN UNIDADES HOSPITALARIAS 80 | S7: MATRICULA: | V7: 95153151 | Y7: CC | AB7: DESCANSO: | AE7: S-D | AH7: No PLAZA | AK7: =VLOOKUP(V7,'PLANTILLA VESP'!A1:L313,2,FALSE) -> 37831
A8: 0
A9: PISO | D9: SERVICIO | J9: F. INGRESO | P9: TIPO DE PLAZA | T9: =VLOOKUP(V7,'PLANTILLA VESP'!A1:L314,11,FALSE) -> OPERATIVA BASE | Y9: ROL.VAC | AD9: MARCA DE INC | AJ9: AÑO: 2025
A10: MES/DIA
A11: ENERO | B11: L | C11: M | D11: M-1 | E11: J-2 | F11: V-3 | G11: S-4 | H11: D-5 | I11: L-6 | J11: M-7 | K11: M-8 | L11: J-9 | M11: V-10 | N11: S-11 | O11: D-12 | P11: L-13 | Q11: M-14 | R11: M-15 | S11: J-16 | T11: V-17 | U11: S-18 | V11: D-19 | W11: L-20 | X11: M-21 | Y11: M-22 | Z11: J-23 | AA11: V-24 | AB11: S-25 | AC11: D-26 | AD11: L-27 | AE11: M-28 | AF11: M-29 | AG11: J-30 | AH11: V-31 | AI11: S | AJ11: D | AK11: L | AL11: M
G12: S
A13: FEBRERO | B13: L | C13: M | D13: M | E13: J | F13: V | G13: S-1 | H13: D-2 | I13: L-3 | J13: M-4 | K13: M-5 | L13: J-6 | M13: V-7 | N13: S-8 | O13: D-9 | P13: L-10 | Q13: M-11 | R13: M-12 | S13: J-13 | T13: V-14 | U13: S-15 | V13: D-16 | W13: L-17 | X13: M-18 | Y13: M-19 | Z13: J-20 | AA13: V-21 | AB13: S-22 | AC13: D-23 | AD13: L-24 | AE13: M-25 | AF13: M-26 | AG13: J-27 | AH13: V- 28 | AI13: S | AJ13: D | AK13: L | AL13: M
AI14: }
A15: MARZO | B15: L | C15: M | D15: M | E15: J | F15: V | G15: S-1 | H15: D-2 | I15: L-3 | J15: M-4 | K15: M-5 | L15: J-6 | M15: V-7 | N15: S-8 | O15: D-9 | P15: L-10 | Q15: M-11 | R15: M-12 | S15: J-13 | T15: V-14 | U15: S-15 | V15: D-16 | W15: L-17 | X15: M-18 | Y15: M-19 | Z15: J-20 | AA15: V-21 | AB15: S-22 | AC15: D-23 | AD15: L-24 | AE15: M-25 | AF15: M-26 | AG15: J-27 | AH15: V- 28 | AI15: S-29 | AJ15: D-30 | AK15: L-31 | AL15: M
A17: ABRIL | B17: L | C17: M-1 | D17: M-2 | E17: J-3 | F17: V-4 | G17: S-5 | H17: D-6 | I17: L-7 | J17: M-8 | K17: M-9 | L17: J-10 | M17: V-11 | N17: S-12 | O17: D-13 | P17: L-14 | Q17: M-15 | R17: M-16 | S17: J-17 | T17: V-18 | U17: S-19 | V17: D-20 | W17: L-21 | X17: M-22 | Y17: M-23 | Z17: J-24 | AA17: V-25 | AB17: S-26 | AC17: D-27 | AD17: L-28 | AE17: M-29 | AF17: M-30 | AG17: J | AH17: V | AI17: S | AJ17: D | AK17: L | AL17: M
A19: MAYO | B19: L | C19: M | D19: M | E19: J-1 | F19: V-2 | G19: S-3 | H19: D-4 | I19: L-5 | J19: M-6 | K19: M-7 | L19: J-8 | M19: V-9 | N19: S-10 | O19: D-11 | P19: L-12 | Q19: M-13 | R19: M-14 | S19: J-15 | T19: V-16 | U19: S-17 | V19: D-18 | W19: L-19 | X19: M-20 | Y19: M-21 | Z19: J-22 | AA19: V-23 | AB19: S-24 | AC19: D-25 | AD19: L-26 | AE19: M-27 | AF19: M-28 | AG19: J-29 | AH19: V-30 | AI19: S-31 | AJ19: D | AK19: L | AL19: M
A21: JUNIO | B21: L | C21: M | D21: M | E21: J | F21: V | G21: S | H21: D-1 | I21: L-2 | J21: M-3 | K21: M-4 | L21: J-5 | M21: V-6 | N21: S-7 | O21: D-8 | P21: L-9 | Q21: M-10 | R21: M-11 | S21: J-12 | T21: V-13 | U21: S-14 | V21: D-15 | W21: L-16 | X21: M-17 | Y21: M-18 | Z21: J-19 | AA21: V-20 | AB21: S-21 | AC21: D-22 | AD21: L-23 | AE21: M-24 | AF21: M-25 | AG21: J-26 | AH21: V- 27 | AI21: S-28 | AJ21: D-29 | AK21: L-30 | AL21: M
A23: JULIO | B23: L | C23: M-1 | D23: M-2 | E23: J-3 | F23: V-4 | G23: S-5 | H23: D-6 | I23: L-7 | J23: M-8 | K23: M-9 | L23: J-10 | M23: V-11 | N23: S-12 | O23: D-13 | P23: L-14 | Q23: M-15 | R23: M-16 | S23: J-17 | T23: V-18 | U23: S-19 | V23: D-20 | W23: L-21 | X23: M-22 | Y23: M-23 | Z23: J-24 | AA23: V-25 | AB23: S-26 | AC23: D-27 | AD23: L-28 | AE23: M-29 | AF23: M-30 | AG23: J-31 | AH23: V | AI23: S | AJ23: D | AK23: L | AL23: M
A25: AGOSTO | B25: L | C25: M | D25: M | E25: J | F25: V-1 | G25: S-2 | H25: D-3 | I25: L-4 | J25: M-5 | K25: M-6 | L25: J-7 | M25: V-8 | N25: S-9 | O25: D-10 | P25: L-11 | Q25: M-12 | R25: M-13 | S25: J-14 | T25: V-15 | U25: S-16 | V25: D-17 | W25: L-18 | X25: M-19 | Y25: M-20 | Z25: J-21 | AA25: V-22 | AB25: S-23 | AC25: D-24 | AD25: L-25 | AE25: M-26 | AF25: M-27 | AG25: J-28 | AH25: V-29 | AI25: S-30 | AJ25: D-31 | AK25: L | AL25: M
A27: SEPTIEMBRE | B27: L-1 | C27: M-2 | D27: M-3 | E27: J-4 | F27: V-5 | G27: S-6 | H27: D-7 | I27: L-8 | J27: M-9 | K27: M-10 | L27: J-11 | M27: V-12 | N27: S-13 | O27: D-14 | P27: L-15 | Q27: M-16 | R27: M-17 | S27: J-18 | T27: V-19 | U27: S-20 | V27: D-21 | W27: L-22 | X27: M-23 | Y27: M-24 | Z27: J-25 | AA27: V- 26 | AB27: S-27 | AC27: D-28 | AD27: L-29 | AE27: M-30 | AF27: M | AG27: J | AH27: V | AI27: S | AJ27: D | AK27: L | AL27: M
A29: OCTUBRE | B29: L | C29: M | D29: M-1 | E29: J-2 | F29: V-3 | G29: S-4 | H29: D-5 | I29: L-6 | J29: M-7 | K29: M-8 | L29: J-9 | M29: V-10 | N29: S-11 | O29: D-12 | P29: L-13 | Q29: M-14 | R29: M-15 | S29: J-16 | T29: V-17 | U29: S-18 | V29: D-19 | W29: L-20 | X29: M-21 | Y29: M-22 | Z29: J-23 | AA29: V-24 | AB29: S-25 | AC29: D-26 | AD29: L-27 | AE29: M-28 | AF29: M-29 | AG29: J-30 | AH29: V-31 | AI29: S | AJ29: D | AK29: L | AL29: M
A31: NOVIEMBRE | B31: L | C31: M | D31: M | E31: J | F31: V | G31: S-1 | H31: D-2 | I31: L-3 | J31: M-4 | K31: M-5 | L31: J-6 | M31: V-7 | N31: S-8 | O31: D-9 | P31: L-10 | Q31: M-11 | R31: M-12 | S31: J-13 | T31: V-14 | U31: S-15 | V31: D-16 | W31: L-17 | X31: M-18 | Y31: M-19 | Z31: J-20 | AA31: V-21 | AB31: S-22 | AC31: D-23 | AD31: L-24 | AE31: M-25 | AF31: M-26 | AG31: J-27 | AH31: V-28 | AI31: S-29 | AJ31: D-30 | AK31: L | AL31: M
A33: DICIEMBRE | B33: L-1 | C33: M-2 | D33: M-3 | E33: J-4 | F33: V-5 | G33: S-6 | H33: D-7 | I33: L-8 | J33: M-9 | K33: M-10 | L33: J-11 | M33: V-12 | N33: S-13 | O33: D-14 | P33: L-15 | Q33: M-16 | R33: M-17 | S33: J-18 | T33: V-19 | U33: S-20 | V33: D-21 | W33: L-22 | X33: M-23 | Z33: J-25 | AA33: V- 26 | AB33: S-27 | AC33: D-28 | AD33: L-29 | AE33: M-30 | AF33: M-31 | AG33: J | AH33: V | AI33: S | AJ33: D | AK33: L | AL33: M
F37: LIC. SANDRA CASTILLO HERNÁNDEZ | AA37: MTRA. AIDEE CASTILLO SANDOVAL
F39: JEFE DE ENFERMERAS | AA39: SUBJEFE DE ENFERMERAS

Sheet L-M
A1: INSTITUTO MEXICANO DEL SEGURO SOCIAL
A2: DIRECCION DE PRESTACIONES MEDICAS COORDINACION DE ATENCION INTREGRAL EN SEGUNDO NIVEL
A3: DEPARTAMENTO DE ENFERMERIA
A4: HOSPITAL GENERAL REGIONAL N0. 200
A5: TECAMAC
A7: NOMBRE: | B7: =VLOOKUP(V7,'PLANTILLA VESP'!A1:L298,3,FALSE) -> ANGELES JUAREZ ARIAN YURITZY | J7: CAT: | L7: =VLOOKUP(V7,'PLANTILLA VESP'!A1:L298,4,FALSE) -> ENFERMERA GENERAL 80 | S7: MATRICULA: | V7: 96156508 | Y7: CC | AB7: DESCANSO: | AE7: =VLOOKUP(V7,'PLANTILLA VESP'!A1:L298,10,FALSE) -> L-M | AH7: No PLAZA | AK7: =VLOOKUP(V7,'PLANTILLA VESP'!A1:L298,2,FALSE) -> 38793
A9: PISO | D9: SERVICIO | J9: F. INGRESO | P9: TIPO DE PLAZA | T9: =VLOOKUP(V7,'PLANTILLA VESP'!A1:L298,11,FALSE) -> CUBRE VACACIONES BASE | Y9: ROL.VAC | AD9: MARCA DE INC | AJ9: AÑO: 2025
A10: MES/DIA
A11: ENERO | B11: L | C11: M | D11: M-1 | E11: J-2 | F11: V-3 | G11: S-4 | H11: D-5 | I11: L-6 | J11: M-7 | K11: M-8 | L11: J-9 | M11: V-10 | N11: S-11 | O11: D-12 | P11: L-13 | Q11: M-14 | R11: M-15 | S11: J-16 | T11: V-17 | U11: S-18 | V11: D-19 | W11: L-20 | X11: M-21 | Y11: M-22 | Z11: J-23 | AA11: V-24 | AB11: S-25 | AC11: D-26 | AD11: L-27 | AE11: M-28 | AF11: M-29 | AG11: J-30 | AH11: V-31 | AI11: S | AJ11: D | AK11: L | AL11: M
A13: FEBRERO | B13: L | C13: M | D13: M | E13: J | F13: V | G13: S-1 | H13: D-2 | I13: L-3 | J13: M-4 | K13: M-5 | L13: J-6 | M13: V-7 | N13: S-8 | O13: D-9 | P13: L-10 | Q13: M-11 | R13: M-12 | S13: J-13 | T13: V-14 | U13: S-15 | V13: D-16 | W13: L-17 | X13: M-18 | Y13: M-19 | Z13: J-20 | AA13: V-21 | AB13: S-22 | AC13: D-23 | AD13: L-24 | AE13: M-25 | AF13: M-26 | AG13: J-27 | AH13: V- 28 | AI13: S | AJ13: D | AK13: L | AL13: M
A15: MARZO | B15: L | C15: M | D15: M | E15: J | F15: V | G15: S-1 | H15: D-2 | I15: L-3 | J15: M-4 | K15: M-5 | L15: J-6 | M15: V-7 | N15: S-8 | O15: D-9 | P15: L-10 | Q15: M-11 | R15: M-12 | S15: J-13 | T15: V-14 | U15: S-15 | V15: D-16 | W15: L-17 | X15: M-18 | Y15: M-19 | Z15: J-20 | AA15: V-21 | AB15: S-22 | AC15: D-23 | AD15: L-24 | AE15: M-25 | AF15: M-26 | AG15: J-27 | AH15: V- 28 | AI15: S-29 | AJ15: D-30 | AK15: L-31 | AL15: M
A17: ABRIL | B17: L | C17: M-1 | D17: M-2 | E17: J-3 | F17: V-4 | G17: S-5 | H17: D-6 | I17: L-7 | J17: M-8 | K17: M-9 | L17: J-10 | M17: V-11 | N17: S-12 | O17: D-13 | P17: L-14 | Q17: M-15 | R17: M-16 | S17: J-17 | T17: V-18 | U17: S-19 | V17: D-20 | W17: L-21 | X17: M-22 | Y17: M-23 | Z17: J-24 | AA17: V-25 | AB17: S-26 | AC17: D-27 | AD17: L-28 | AE17: M-29 | AF17: M-30 | AG17: J | AH17: V | AI17: S | AJ17: D | AK17: L | AL17: M
A19: MAYO | B19: L | C19: M | D19: M | E19: J-1 | F19: V-2 | G19: S-3 | H19: D-4 | I19: L-5 | J19: M-6 | K19: M-7 | L19: J-8 | M19: V-9 | N19: S-10 | O19: D-11 | P19: L-12 | Q19: M-13 | R19: M-14 | S19: J-15 | T19: V-16 | U19: S-17 | V19: D-18 | W19: L-19 | X19: M-20 | Y19: M-21 | Z19: J-22 | AA19: V-23 | AB19: S-24 | AC19: D-25 | AD19: L-26 | AE19: M-27 | AF19: M-28 | AG19: J-29 | AH19: V-30 | AI19: S-31 | AJ19: D | AK19: L | AL19: M
A21: JUNIO | B21: L | C21: M | D21: M | E21: J | F21: V | G21: S | H21: D-1 | I21: L-2 | J21: M-3 | K21: M-4 | L21: J-5 | M21: V-6 | N21: S-7 | O21: D-8 | P21: L-9 | Q21: M-10 | R21: M-11 | S21: J-12 | T21: V-13 | U21: S-14 | V21: D-15 | W21: L-16 | X21: M-17 | Y21: M-18 | Z21: J-19 | AA21: V-20 | AB21: S-21 | AC21: D-22 | AD21: L-23 | AE21: M-24 | AF21: M-25 | AG21: J-26 | AH21: V- 27 | AI21: S-28 | AJ21: D-29 | AK21: L-30 | AL21: M
A23: JULIO | B23: L | C23: M-1 | D23: M-2 | E23: J-3 | F23: V-4 | G23: S-5 | H23: D-6 | I23: L-7 | J23: M-8 | K23: M-9 | L23: J-10 | M23: V-11 | N23: S-12 | O23: D-13 | P23: L-14 | Q23: M-15 | R23: M-16 | S23: J-17 | T23: V-18 | U23: S-19 | V23: D-20 | W23: L-21 | X23: M-22 | Y23: M-23 | Z23: J-24 | AA23: V-25 | AB23: S-26 | AC23: D-27 | AD23: L-28 | AE23: M-29 | AF23: M-30 | AG23: J-31 | AH23: V | AI23: S | AJ23: D | AK23: L | AL23: M
A25: AGOSTO | B25: L | C25: M | D25: M | E25: J | F25: V-1 | G25: S-2 | H25: D-3 | I25: L-4 | J25: M-5 | K25: M-6 | L25: J-7 | M25: V-8 | N25: S-9 | O25: D-10 | P25: L-11 | Q25: M-12 | R25: M-13 | S25: J-14 | T25: V-15 | U25: S-16 | V25: D-17 | W25: L-18 | X25: M-19 | Y25: M-20 | Z25: J-21 | AA25: V-22 | AB25: S-23 | AC25: D-24 | AD25: L-25 | AE25: M-26 | AF25: M-27 | AG25: J-28 | AH25: V-29 | AI25: S-30 | AJ25: D-31 | AK25: L | AL25: M
A27: SEPTIEMBRE | B27: L-1 | C27: M-2 | D27: M-3 | E27: J-4 | F27: V-5 | G27: S-6 | H27: D-7 | I27: L-8 | J27: M-9 | K27: M-10 | L27: J-11 | M27: V-12 | N27: S-13 | O27: D-14 | P27: L-15 | Q27: M-16 | R27: M-17 | S27: J-18 | T27: V-19 | U27: S-20 | V27: D-21 | W27: L-22 | X27: M-23 | Y27: M-24 | Z27: J-25 | AA27: V- 26 | AB27: S-27 | AC27: D-28 | AD27: L-29 | AE27: M-30 | AF27: M | AG27: J | AH27: V | AI27: S | AJ27: D | AK27: L | AL27: M
A29: OCTUBRE | B29: L | C29: M | D29: M-1 | E29: J-2 | F29: V-3 | G29: S-4 | H29: D-5 | I29: L-6 | J29: M-7 | K29: M-8 | L29: J-9 | M29: V-10 | N29: S-11 | O29: D-12 | P29: L-13 | Q29: M-14 | R29: M-15 | S29: J-16 | T29: V-17 | U29: S-18 | V29: D-19 | W29: L-20 | X29: M-21 | Y29: M-22 | Z29: J-23 | AA29: V-24 | AB29: S-25 | AC29: D-26 | AD29: L-27 | AE29: M-28 | AF29: M-29 | AG29: J-30 | AH29: V-31 | AI29: S | AJ29: D | AK29: L | AL29: M
A31: NOVIEMBRE | B31: L | C31: M | D31: M | E31: J | F31: V | G31: S-1 | H31: D-2 | I31: L-3 | J31: M-4 | K31: M-5 | L31: J-6 | M31: V-7 | N31: S-8 | O31: D-9 | P31: L-10 | Q31: M-11 | R31: M-12 | S31: J-13 | T31: V-14 | U31: S-15 | V31: D-16 | W31: L-17 | X31: M-18 | Y31: M-19 | Z31: J-20 | AA31: V-21 | AB31: S-22 | AC31: D-23 | AD31: L-24 | AE31: M-25 | AF31: M-26 | AG31: J-27 | AH31: V-28 | AI31: S-29 | AJ31: D-30 | AK31: L | AL31: M
A33: DICIEMBRE | B33: L-1 | C33: M-2 | D33: M-3 | E33: J-4 | F33: V-5 | G33: S-6 | H33: D-7 | I33: L-8 | J33: M-9 | K33: M-10 | L33: J-11 | M33: V-12 | N33: S-13 | O33: D-14 | P33: L-15 | Q33: M-16 | R33: M-17 | S33: J-18 | T33: V-19 | U33: S-20 | V33: D-21 | W33: L-22 | X33: M-23 | Y33: M-24 | Z33: J-25 | AA33: V- 26 | AB33: S-27 | AC33: D-28 | AD33: L-29 | AE33: M-30 | AF33: M-31 | AG33: J | AH33: V | AI33: S | AJ33: D | AK33: L | AL33: M
F37: LIC. SANDRA CASTILLO HERNÁNDEZ | AA37: MTRA. AIDEE CASTILLO SANDOVAL
F39: JEFE DE ENFERMERAS | AA39: SUBJEFE DE ENFERMERAS

Sheet M-J
A2: DIRECCION DE PRESTACIONES MEDICAS COORDINACION DE ATENCION INTREGRAL EN SEGUNDO NIVEL
A3: DEPARTAMENTO DE ENFERMERIA
A4: HOSPITAL GENERAL REGIONAL N0. 200
A5: TECAMAC
A7: NOMBRE: | B7: =VLOOKUP(V7,'PLANTILLA VESP'!A1:L298,3,FALSE) -> GONZALEZ QUIROZ ALMA ROCIO | J7: CAT: | L7: =VLOOKUP(V7,'PLANTILLA VESP'!A1:L298,4,FALSE) -> ENFERMERA JEFE DE PISO 80 | S7: MATRICULA: | V7: 98152859 | Y7: CC | AB7: DESCANSO: | AE7: =VLOOKUP(V7,'PLANTILLA VESP'!A1:L298,10,FALSE) -> M-J | AH7: No PLAZA | AK7: =VLOOKUP(V7,'PLANTILLA VESP'!A1:L298,2,FALSE) -> 71534
A8: 97156372
A9: PISO | D9: SERVICIO | J9: F. INGRESO | P9: TIPO DE PLAZA | T9: =VLOOKUP(V7,'PLANTILLA VESP'!A1:L298,11,FALSE) -> CUBRE DESCANSOS BASE | Y9: ROL.VAC | AD9: MARCA DE INC | AJ9: AÑO: 2025
A10: MES/DIA
A11: ENERO | B11: L | C11: M | D11: M-1 | E11: J-2 | F11: V-3 | G11: S-4 | H11: D-5 | I11: L-6 | J11: M-7 | K11: M-8 | L11: J-9 | M11: V-10 | N11: S-11 | O11: D-12 | P11: L-13 | Q11: M-14 | R11: M-15 | S11: J-16 | T11: V-17 | U11: S-18 | V11: D-19 | W11: L-20 | X11: M-21 | Y11: M-22 | Z11: J-23 | AA11: V-24 | AB11: S-25 | AC11: D-26 | AD11: L-27 | AE11: M-28 | AF11: M-29 | AG11: J-30 | AH11: V-31 | AI11: S | AJ11: D | AK11: L | AL11: M
A13: FEBRERO | B13: L | C13: M | D13: M | E13: J | F13: V | G13: S-1 | H13: D-2 | I13: L-3 | J13: M-4 | K13: M-5 | L13: J-6 | M13: V-7 | N13: S-8 | O13: D-9 | P13: L-10 | Q13: M-11 | R13: M-12 | S13: J-13 | T13: V-14 | U13: S-15 | V13: D-16 | W13: L-17 | X13: M-18 | Y13: M-19 | Z13: J-20 | AA13: V-21 | AB13: S-22 | AC13: D-23 | AD13: L-24 | AE13: M-25 | AF13: M-26 | AG13: J-27 | AH13: V- 28 | AI13: S | AJ13: D | AK13: L | AL13: M
A15: MARZO | B15: L | C15: M | D15: M | E15: J | F15: V | G15: S-1 | H15: D-2 | I15: L-3 | J15: M-4 | K15: M-5 | L15: J-6 | M15: V-7 | N15: S-8 | O15: D-9 | P15: L-10 | Q15: M-11 | R15: M-12 | S15: J-13 | T15: V-14 | U15: S-15 | V15: D-16 | W15: L-17 | X15: M-18 | Y15: M-19 | Z15: J-20 | AA15: V-21 | AB15: S-22 | AC15: D-23 | AD15: L-24 | AE15: M-25 | AF15: M-26 | AG15: J-27 | AH15: V- 28 | AI15: S-29 | AJ15: D-30 | AK15: L-31 | AL15: M
A17: ABRIL | B17: L | C17: M-1 | D17: M-2 | E17: J-3 | F17: V-4 | G17: S-5 | H17: D-6 | I17: L-7 | J17: M-8 | K17: M-9 | L17: J-10 | M17: V-11 | N17: S-12 | O17: D-13 | P17: L-14 | Q17: M-15 | R17: M-16 | S17: J-17 | T17: V-18 | U17: S-19 | V17: D-20 | W17: L-21 | X17: M-22 | Y17: M-23 | Z17: J-24 | AA17: V-25 | AB17: S-26 | AC17: D-27 | AD17: L-28 | AE17: M-29 | AF17: M-30 | AG17: J | AH17: V | AI17: S | AJ17: D | AK17: L | AL17: M
A19: MAYO | B19: L | C19: M | D19: M | E19: J-1 | F19: V-2 | G19: S-3 | H19: D-4 | I19: L-5 | J19: M-6 | K19: M-7 | L19: J-8 | M19: V-9 | N19: S-10 | O19: D-11 | P19: L-12 | Q19: M-13 | R19: M-14 | S19: J-15 | T19: V-16 | U19: S-17 | V19: D-18 | W19: L-19 | X19: M-20 | Y19: M-21 | Z19: J-22 | AA19: V-23 | AB19: S-24 | AC19: D-25 | AD19: L-26 | AE19: M-27 | AF19: M-28 | AG19: J-29 | AH19: V-30 | AI19: S-31 | AJ19: D | AK19: L | AL19: M
A21: JUNIO | B21: L | C21: M | D21: M | E21: J | F21: V | G21: S | H21: D-1 | I21: L-2 | J21: M-3 | K21: M-4 | L21: J-5 | M21: V-6 | N21: S-7 | O21: D-8 | P21: L-9 | Q21: M-10 | R21: M-11 | S21: J-12 | T21: V-13 | U21: S-14 | V21: D-15 | W21: L-16 | X21: M-17 | Y21: M-18 | Z21: J-19 | AA21: V-20 | AB21: S-21 | AC21: D-22 | AD21: L-23 | AE21: M-24 | AF21: M-25 | AG21: J-26 | AH21: V- 27 | AI21: S-28 | AJ21: D-29 | AK21: L-30 | AL21: M
A23: JULIO | B23: L | C23: M-1 | D23: M-2 | E23: J-3 | F23: V-4 | G23: S-5 | H23: D-6 | I23: L-7 | J23: M-8 | K23: M-9 | L23: J-10 | M23: V-11 | N23: S-12 | O23: D-13 | P23: L-14 | Q23: M-15 | R23: M-16 | S23: J-17 | T23: V-18 | U23: S-19 | V23: D-20 | W23: L-21 | X23: M-22 | Y23: M-23 | Z23: J-24 | AA23: V-25 | AB23: S-26 | AC23: D-27 | AD23: L-28 | AE23: M-29 | AF23: M-30 | AG23: J-31 | AH23: V | AI23: S | AJ23: D | AK23: L | AL23: M
A25: AGOSTO | B25: L | C25: M | D25: M | E25: J | F25: V-1 | G25: S-2 | H25: D-3 | I25: L-4 | J25: M-5 | K25: M-6 | L25: J-7 | M25: V-8 | N25: S-9 | O25: D-10 | P25: L-11 | Q25: M-12 | R25: M-13 | S25: J-14 | T25: V-15 | U25: S-16 | V25: D-17 | W25: L-18 | X25: M-19 | Y25: M-20 | Z25: J-21 | AA25: V-22 | AB25: S-23 | AC25: D-24 | AD25: L-25 | AE25: M-26 | AF25: M-27 | AG25: J-28 | AH25: V-29 | AI25: S-30 | AJ25: D-31 | AK25: L | AL25: M
A27: SEPTIEMBRE | B27: L-1 | C27: M-2 | D27: M-3 | E27: J-4 | F27: V-5 | G27: S-6 | H27: D-7 | I27: L-8 | J27: M-9 | K27: M-10 | L27: J-11 | M27: V-12 | N27: S-13 | O27: D-14 | P27: L-15 | Q27: M-16 | R27: M-17 | S27: J-18 | T27: V-19 | U27: S-20 | V27: D-21 | W27: L-22 | X27: M-23 | Y27: M-24 | Z27: J-25 | AA27: V- 26 | AB27: S-27 | AC27: D-28 | AD27: L-29 | AE27: M-30 | AF27: M | AG27: J | AH27: V | AI27: S | AJ27: D | AK27: L | AL27: M
A29: OCTUBRE | B29: L | C29: M | D29: M-1 | E29: J-2 | F29: V-3 | G29: S-4 | H29: D-5 | I29: L-6 | J29: M-7 | K29: M-8 | L29: J-9 | M29: V-10 | N29: S-11 | O29: D-12 | P29: L-13 | Q29: M-14 | R29: M-15 | S29: J-16 | T29: V-17 | U29: S-18 | V29: D-19 | W29: L-20 | X29: M-21 | Y29: M-22 | Z29: J-23 | AA29: V-24 | AB29: S-25 | AC29: D-26 | AD29: L-27 | AE29: M-28 | AF29: M-29 | AG29: J-30 | AH29: V-31 | AI29: S | AJ29: D | AK29: L | AL29: M
A31: NOVIEMBRE | B31: L | C31: M | D31: M | E31: J | F31: V | G31: S-1 | H31: D-2 | I31: L-3 | J31: M-4 | K31: M-5 | L31: J-6 | M31: V-7 | N31: S-8 | O31: D-9 | P31: L-10 | Q31: M-11 | R31: M-12 | S31: J-13 | T31: V-14 | U31: S-15 | V31: D-16 | W31: L-17 | X31: M-18 | Y31: M-19 | Z31: J-20 | AA31: V-21 | AB31: S-22 | AC31: D-23 | AD31: L-24 | AE31: M-25 | AF31: M-26 | AG31: J-27 | AH31: V-28 | AI31: S-29 | AJ31: D-30 | AK31: L | AL31: M
A33: DICIEMBRE | B33: L-1 | C33: M-2 | D33: M-3 | E33: J-4 | F33: V-5 | G33: S-6 | H33: D-7 | I33: L-8 | J33: M-9 | K33: M-10 | L33: J-11 | M33: V-12 | N33: S-13 | O33: D-14 | P33: L-15 | Q33: M-16 | R33: M-17 | S33: J-18 | T33: V-19 | U33: S-20 | V33: D-21 | W33: L-22 | X33: M-23 | Y33: M-24 | Z33: J-25 | AA33: V- 26 | AB33: S-27 | AC33: D-28 | AD33: L-29 | AE33: M-30 | AF33: M-31 | AG33: J | AH33: V | AI33: S | AJ33: D | AK33: L | AL33: M
F37: LIC. SANDRA CASTILLO HERNÁNDEZ | AA37: MTRA. AIDEE CASTILLO SANDOVAL
F39: JEFE DE ENFERMERAS | AA39: SUBJEFE DE ENFERMERAS

Sheet M-M
A1: INSTITUTO MEXICANO DEL SEGURO SOCIAL
A2: DIRECCION DE PRESTACIONES MEDICAS COORDINACION DE ATENCION INTREGRAL EN SEGUNDO NIVEL
A3: DEPARTAMENTO DE ENFERMERIA
A4: HOSPITAL GENERAL REGIONAL N0. 200
A5: TECAMAC
A7: NOMBRE: | B7: =VLOOKUP(V7,'PLANTILLA VESP'!A1:L298,3,FALSE) -> GARNICA CERVANTES JOSELINE MONTSERRAT | J7: CAT: | L7: =VLOOKUP(V7,'PLANTILLA VESP'!A1:L298,4,FALSE) -> AUX DE ENFERMERIA GRAL 80 | S7: MATRICULA: | V7: 96158679 | Y7: CC | AB7: DESCANSO: | AE7: =VLOOKUP(V7,'PLANTILLA VESP'!A1:L298,10,FALSE) -> M-M | AH7: No PLAZA | AK7: =VLOOKUP(V7,'PLANTILLA VESP'!A1:L298,2,FALSE) -> 38421
A9: PISO | D9: SERVICIO | J9: F. INGRESO | P9: TIPO DE PLAZA | T9: =VLOOKUP(V7,'PLANTILLA VESP'!A1:L298,11,FALSE) -> CUBRE VACACIONES BASE | Y9: ROL.VAC | AD9: MARCA DE INC | AJ9: AÑO: 2025
A10: MES/DIA
A11: ENERO | B11: L | C11: M | D11: M-1 | E11: J-2 | F11: V-3 | G11: S-4 | H11: D-5 | I11: L-6 | J11: M-7 | K11: M-8 | L11: J-9 | M11: V-10 | N11: S-11 | O11: D-12 | P11: L-13 | Q11: M-14 | R11: M-15 | S11: J-16 | T11: V-17 | U11: S-18 | V11: D-19 | W11: L-20 | X11: M-21 | Y11: M-22 | Z11: J-23 | AA11: V-24 | AB11: S-25 | AC11: D-26 | AD11: L-27 | AE11: M-28 | AF11: M-29 | AG11: J-30 | AH11: V-31 | AI11: S | AJ11: D | AK11: L | AL11: M
A13: FEBRERO | B13: L | C13: M | D13: M | E13: J | F13: V | G13: S-1 | H13: D-2 | I13: L-3 | J13: M-4 | K13: M-5 | L13: J-6 | M13: V-7 | N13: S-8 | O13: D-9 | P13: L-10 | Q13: M-11 | R13: M-12 | S13: J-13 | T13: V-14 | U13: S-15 | V13: D-16 | W13: L-17 | X13: M-18 | Y13: M-19 | Z13: J-20 | AA13: V-21 | AB13: S-22 | AC13: D-23 | AD13: L-24 | AE13: M-25 | AF13: M-26 | AG13: J-27 | AH13: V- 28 | AI13: S | AJ13: D | AK13: L | AL13: M
A15: MARZO | B15: L | C15: M | D15: M | E15: J | F15: V | G15: S-1 | H15: D-2 | I15: L-3 | J15: M-4 | K15: M-5 | L15: J-6 | M15: V-7 | N15: S-8 | O15: D-9 | P15: L-10 | Q15: M-11 | R15: M-12 | S15: J-13 | T15: V-14 | U15: S-15 | V15: D-16 | W15: L-17 | X15: M-18 | Y15: M-19 | Z15: J-20 | AA15: V-21 | AB15: S-22 | AC15: D-23 | AD15: L-24 | AE15: M-25 | AF15: M-26 | AG15: J-27 | AH15: V- 28 | AI15: S-29 | AJ15: D-30 | AK15: L-31 | AL15: M
A17: ABRIL | C17: M-1 | D17: M-2 | E17: J-3 | F17: V-4 | G17: S-5 | H17: D-6 | I17: L-7 | J17: M-8 | K17: M-9 | L17: J-10 | M17: V-11 | N17: S-12 | O17: D-13 | P17: L-14 | Q17: M-15 | R17: M-16 | S17: J-17 | T17: V-18 | U17: S-19 | V17: D-20 | W17: L-21 | X17: M-22 | Y17: M-23 | Z17: J-24 | AA17: V-25 | AB17: S-26 | AC17: D-27 | AD17: L-28 | AE17: M-29 | AF17: M-30 | AG17: J | AH17: V | AI17: S | AJ17: D | AK17: L | AL17: M
A19: MAYO | B19: L | C19: M | D19: M | E19: J-1 | F19: V-2 | G19: S-3 | H19: D-4 | I19: L-5 | J19: M-6 | K19: M-7 | L19: J-8 | M19: V-9 | N19: S-10 | O19: D-11 | P19: L-12 | Q19: M-13 | R19: M-14 | S19: J-15 | T19: V-16 | U19: S-17 | V19: D-18 | W19: L-19 | X19: M-20 | Y19: M-21 | Z19: J-22 | AA19: V-23 | AB19: S-24 | AC19: D-25 | AD19: L-26 | AE19: M-27 | AF19: M-28 | AG19: J-29 | AH19: V-30 | AI19: S-31 | AJ19: D | AK19: L | AL19: M
A21: JUNIO | B21: L | C21: M | D21: M | E21: J | F21: V | G21: S | H21: D-1 | I21: L-2 | J21: M-3 | K21: M-4 | L21: J-5 | M21: V-6 | N21: S-7 | O21: D-8 | P21: L-9 | Q21: M-10 | R21: M-11 | S21: J-12 | T21: V-13 | U21: S-14 | V21: D-15 | W21: L-16 | X21: M-17 | Y21: M-18 | Z21: J-19 | AA21: V-20 | AB21: S-21 | AC21: D-22 | AD21: L-23 | AE21: M-24 | AF21: M-25 | AG21: J-26 | AH21: V- 27 | AI21: S-28 | AJ21: D-29 | AK21: L-30 | AL21: M
A23: JULIO | B23: L | C23: M-1 | D23: M-2 | E23: J-3 | F23: V-4 | G23: S-5 | H23: D-6 | I23: L-7 | J23: M-8 | K23: M-9 | L23: J-10 | M23: V-11 | N23: S-12 | O23: D-13 | P23: L-14 | Q23: M-15 | R23: M-16 | S23: J-17 | T23: V-18 | U23: S-19 | V23: D-20 | W23: L-21 | X23: M-22 | Y23: M-23 | Z23: J-24 | AA23: V-25 | AB23: S-26 | AC23: D-27 | AD23: L-28 | AE23: M-29 | AF23: M-30 | AG23: J-31 | AH23: V | AI23: S | AJ23: D | AK23: L | AL23: M
A25: AGOSTO | B25: L | C25: M | D25: M | E25: J | F25: V-1 | G25: S-2 | H25: D-3 | I25: L-4 | J25: M-5 | K25: M-6 | L25: J-7 | M25: V-8 | N25: S-9 | O25: D-10 | P25: L-11 | Q25: M-12 | R25: M-13 | S25: J-14 | T25: V-15 | U25: S-16 | V25: D-17 | W25: L-18 | X25: M-19 | Y25: M-20 | Z25: J-21 | AA25: V-22 | AB25: S-23 | AC25: D-24 | AD25: L-25 | AE25: M-26 | AF25: M-27 | AG25: J-28 | AH25: V-29 | AI25: S-30 | AJ25: D-31 | AK25: L | AL25: M
A27: SEPTIEMBRE | B27: L-1 | C27: M-2 | D27: M-3 | E27: J-4 | F27: V-5 | G27: S-6 | H27: D-7 | I27: L-8 | J27: M-9 | K27: M-10 | L27: J-11 | M27: V-12 | N27: S-13 | O27: D-14 | P27: L-15 | Q27: M-16 | R27: M-17 | S27: J-18 | T27: V-19 | U27: S-20 | V27: D-21 | W27: L-22 | X27: M-23 | Y27: M-24 | Z27: J-25 | AA27: V- 26 | AB27: S-27 | AC27: D-28 | AD27: L-29 | AE27: M-30 | AF27: M | AG27: J | AH27: V | AI27: S | AJ27: D | AK27: L | AL27: M
A29: OCTUBRE | B29: L | C29: M | D29: M-1 | E29: J-2 | F29: V-3 | G29: S-4 | H29: D-5 | I29: L-6 | J29: M-7 | K29: M-8 | L29: J-9 | M29: V-10 | N29: S-11 | O29: D-12 | P29: L-13 | Q29: M-14 | R29: M-15 | S29: J-16 | T29: V-17 | U29: S-18 | V29: D-19 | W29: L-20 | X29: M-21 | Y29: M-22 | Z29: J-23 | AA29: V-24 | AB29: S-25 | AC29: D-26 | AD29: L-27 | AE29: M-28 | AF29: M-29 | AG29: J-30 | AH29: V-31 | AI29: S | AJ29: D | AK29: L | AL29: M
A31: NOVIEMBRE | B31: L | C31: M | D31: M | E31: J | F31: V | G31: S-1 | H31: D-2 | I31: L-3 | J31: M-4 | K31: M-5 | L31: J-6 | M31: V-7 | N31: S-8 | O31: D-9 | P31: L-10 | Q31: M-11 | R31: M-12 | S31: J-13 | T31: V-14 | U31: S-15 | V31: D-16 | W31: L-17 | X31: M-18 | Y31: M-19 | Z31: J-20 | AA31: V-21 | AB31: S-22 | AC31: D-23 | AD31: L-24 | AE31: M-25 | AF31: M-26 | AG31: J-27 | AH31: V-28 | AI31: S-29 | AJ31: D-30 | AK31: L | AL31: M
A33: DICIEMBRE | B33: L-1 | C33: M-2 | D33: M-3 | E33: J-4 | F33: V-5 | G33: S-6 | H33: D-7 | I33: L-8 | J33: M-9 | K33: M-10 | L33: J-11 | M33: V-12 | N33: S-13 | O33: D-14 | P33: L-15 | Q33: M-16 | R33: M-17 | S33: J-18 | T33: V-19 | U33: S-20 | V33: D-21 | W33: L-22 | X33: M-23 | Y33: M-24 | Z33: J-25 | AA33: V- 26 | AB33: S-27 | AC33: D-28 | AD33: L-29 | AE33: M-30 | AF33: M-31 | AG33: J | AH33: V | AI33: S | AJ33: D | AK33: L | AL33: M
F37: LIC. SANDRA CASTILLO HERNÁNDEZ | AA37: MTRA. AIDEE CASTILLO SANDOVAL
F39: JEFE DE ENFERMERAS | AA39: SUBJEFE DE ENFERMERAS

Sheet J-V
A1: INSTITUTO A196:AL243MEXICANO DEL SEGURO SOCIAL
A2: DIRECCION DE PRESTACIONES MEDICAS COORDINACION DE ATENCION INTREGRAL EN SEGUNDO NIVEL
A3: DEPARTAMENTO DE ENFERMERIA
A4: HOSPITAL GENERAL REGIONAL N0. 200
A5: TECAMAC
A7: NOMBRE: | B7: =VLOOKUP(V7,'PLANTILLA VESP'!A1:L298,3,FALSE) -> HERNANDEZ GARNICA CARLOS IVAN (02) | J7: CAT: | L7: =VLOOKUP(V7,'PLANTILLA VESP'!A1:L298,4,FALSE) -> CAMILLERO EN UNIDADES HOSPITALARIAS 80 | S7: MATRICULA: | V7: 95151982 | Y7: CC | AB7: DESCANSO: | AE7: =VLOOKUP(V7,'PLANTILLA VESP'!A1:L298,10,FALSE) -> J-V | AH7: No PLAZA | AK7: =VLOOKUP(V7,'PLANTILLA VESP'!A1:L298,2,FALSE) -> 37902
A9: PISO | D9: SERVICIO | J9: F. INGRESO | P9: TIPO DE PLAZA | T9: =VLOOKUP(V7,'PLANTILLA VESP'!A1:L298,11,FALSE) -> OPERATIVA BASE | Y9: ROL.VAC | AD9: MARCA DE INC | AJ9: AÑO: 2025
A10: MES/DIA
A11: ENERO | B11: L | C11: M | D11: M-1 | E11: J-2 | F11: V-3 | G11: S-4 | H11: D-5 | I11: L-6 | J11: M-7 | K11: M-8 | L11: J-9 | M11: V-10 | N11: S-11 | O11: D-12 | P11: L-13 | R11: M-15 | S11: J-16 | T11: V-17 | U11: S-18 | V11: D-19 | W11: L-20 | X11: M-21 | Y11: M-22 | Z11: J-23 | AA11: V-24 | AB11: S-25 | AC11: D-26 | AD11: L-27 | AE11: M-28 | AF11: M-29 | AG11: J-30 | AH11: V-31 | AI11: S | AJ11: D | AK11: L | AL11: M
A13: FEBRERO | B13: L | C13: M | D13: M | E13: J | F13: V | G13: S-1 | H13: D-2 | I13: L-3 | J13: M-4 | K13: M-5 | L13: J-6 | M13: V-7 | N13: S-8 | O13: D-9 | P13: L-10 | Q13: M-11 | R13: M-12 | S13: J-13 | T13: V-14 | U13: S-15 | V13: D-16 | W13: L-17 | X13: M-18 | Y13: M-19 | Z13: J-20 | AA13: V-21 | AB13: S-22 | AC13: D-23 | AD13: L-24 | AE13: M-25 | AF13: M-26 | AG13: J-27 | AH13: V- 28 | AI13: S | AJ13: D | AK13: L | AL13: M
A15: MARZO | B15: L | C15: M | D15: M | E15: J | F15: V | G15: S-1 | H15: D-2 | I15: L-3 | J15: M-4 | K15: M-5 | L15: J-6 | M15: V-7 | N15: S-8 | O15: D-9 | P15: L-10 | Q15: M-11 | R15: M-12 | S15: J-13 | T15: V-14 | U15: S-15 | V15: D-16 | W15: L-17 | X15: M-18 | Y15: M-19 | Z15: J-20 | AA15: V-21 | AB15: S-22 | AC15: D-23 | AD15: L-24 | AE15: M-25 | AF15: M-26 | AG15: J-27 | AH15: V- 28 | AI15: S-29 | AJ15: D-30 | AK15: L-31 | AL15: M
A17: ABRIL | B17: L | C17: M-1 | D17: M-2 | E17: J-3 | F17: V-4 | G17: S-5 | H17: D-6 | I17: L-7 | J17: M-8 | K17: M-9 | L17: J-10 | M17: V-11 | N17: S-12 | O17: D-13 | P17: L-14 | Q17: M-15 | R17: M-16 | S17: J-17 | T17: V-18 | U17: S-19 | V17: D-20 | W17: L-21 | X17: M-22 | Y17: M-23 | Z17: J-24 | AA17: V-25 | AB17: S-26 | AC17: D-27 | AD17: L-28 | AE17: M-29 | AF17: M-30 | AG17: J | AH17: V | AI17: S | AJ17: D | AK17: L | AL17: M
A19: MAYO | B19: L | C19: M | D19: M | E19: J-1 | F19: V-2 | G19: S-3 | H19: D-4 | I19: L-5 | J19: M-6 | K19: M-7 | L19: J-8 | M19: V-9 | N19: S-10 | O19: D-11 | P19: L-12 | Q19: M-13 | R19: M-14 | S19: J-15 | T19: V-16 | U19: S-17 | V19: D-18 | W19: L-19 | X19: M-20 | Y19: M-21 | Z19: J-22 | AA19: V-23 | AB19: S-24 | AC19: D-25 | AD19: L-26 | AE19: M-27 | AF19: M-28 | AG19: J-29 | AH19: V-30 | AI19: S-31 | AJ19: D | AK19: L | AL19: M
A21: JUNIO | B21: L | C21: M | D21: M | E21: J | F21: V | G21: S | H21: D-1 | I21: L-2 | J21: M-3 | K21: M-4 | L21: J-5 | M21: V-6 | N21: S-7 | O21: D-8 | P21: L-9 | Q21: M-10 | R21: M-11 | S21: J-12 | T21: V-13 | U21: S-14 | V21: D-15 | W21: L-16 | X21: M-17 | Y21: M-18 | Z21: J-19 | AA21: V-20 | AB21: S-21 | AC21: D-22 | AD21: L-23 | AE21: M-24 | AF21: M-25 | AG21: J-26 | AH21: V- 27 | AI21: S-28 | AJ21: D-29 | AK21: L-30 | AL21: M
A23: JULIO | B23: L | C23: M-1 | D23: M-2 | E23: J-3 | F23: V-4 | G23: S-5 | H23: D-6 | I23: L-7 | J23: M-8 | K23: M-9 | L23: J-10 | M23: V-11 | N23: S-12 | O23: D-13 | P23: L-14 | Q23: M-15 | R23: M-16 | S23: J-17 | T23: V-18 | U23: S-19 | V23: D-20 | W23: L-21 | X23: M-22 | Y23: M-23 | Z23: J-24 | AA23: V-25 | AB23: S-26 | AC23: D-27 | AD23: L-28 | AE23: M-29 | AF23: M-30 | AG23: J-31 | AH23: V | AI23: S | AJ23: D | AK23: L | AL23: M
A25: AGOSTO | B25: L | C25: M | D25: M | E25: J | F25: V-1 | G25: S-2 | H25: D-3 | I25: L-4 | J25: M-5 | K25: M-6 | L25: J-7 | M25: V-8 | N25: S-9 | O25: D-10 | P25: L-11 | Q25: M-12 | R25: M-13 | S25: J-14 | T25: V-15 | U25: S-16 | V25: D-17 | W25: L-18 | X25: M-19 | Y25: M-20 | Z25: J-21 | AA25: V-22 | AB25: S-23 | AC25: D-24 | AD25: L-25 | AE25: M-26 | AF25: M-27 | AG25: J-28 | AH25: V-29 | AI25: S-30 | AJ25: D-31 | AK25: L | AL25: M
A27: SEPTIEMBRE | B27: L-1 | C27: M-2 | D27: M-3 | E27: J-4 | F27: V-5 | G27: S-6 | H27: D-7 | I27: L-8 | J27: M-9 | K27: M-10 | L27: J-11 | M27: V-12 | N27: S-13 | O27: D-14 | P27: L-15 | Q27: M-16 | R27: M-17 | S27: J-18 | T27: V-19 | U27: S-20 | V27: D-21 | W27: L-22 | X27: M-23 | Y27: M-24 | Z27: J-25 | AA27: V- 26 | AB27: S-27 | AC27: D-28 | AD27: L-29 | AE27: M-30 | AF27: M | AG27: J | AH27: V | AI27: S | AJ27: D | AK27: L | AL27: M
A29: OCTUBRE | B29: L | C29: M | D29: M-1 | E29: J-2 | F29: V-3 | G29: S-4 | H29: D-5 | I29: L-6 | J29: M-7 | K29: M-8 | L29: J-9 | M29: V-10 | N29: S-11 | O29: D-12 | P29: L-13 | Q29: M-14 | R29: M-15 | S29: J-16 | T29: V-17 | U29: S-18 | V29: D-19 | W29: L-20 | X29: M-21 | Y29: M-22 | Z29: J-23 | AA29: V-24 | AB29: S-25 | AC29: D-26 | AD29: L-27 | AE29: M-28 | AF29: M-29 | AG29: J-30 | AH29: V-31 | AI29: S | AJ29: D | AK29: L | AL29: M
A31: NOVIEMBRE | B31: L | C31: M | D31: M | E31: J | F31: V | G31: S-1 | H31: D-2 | I31: L-3 | J31: M-4 | K31: M-5 | L31: J-6 | M31: V-7 | N31: S-8 | O31: D-9 | P31: L-10 | Q31: M-11 | R31: M-12 | S31: J-13 | T31: V-14 | U31: S-15 | V31: D-16 | W31: L-17 | X31: M-18 | Y31: M-19 | Z31: J-20 | AA31: V-21 | AB31: S-22 | AC31: D-23 | AD31: L-24 | AE31: M-25 | AF31: M-26 | AG31: J-27 | AH31: V-28 | AI31: S-29 | AJ31: D-30 | AK31: L | AL31: M
A33: DICIEMBRE | B33: L-1 | C33: M-2 | D33: M-3 | E33: J-4 | F33: V-5 | G33: S-6 | H33: D-7 | I33: L-8 | J33: M-9 | K33: M-10 | L33: J-11 | M33: V-12 | N33: S-13 | O33: D-14 | P33: L-15 | Q33: M-16 | R33: M-17 | S33: J-18 | T33: V-19 | U33: S-20 | V33: D-21 | W33: L-22 | X33: M-23 | Y33: M-24 | Z33: J-25 | AA33: V- 26 | AB33: S-27 | AC33: D-28 | AD33: L-29 | AE33: M-30 | AF33: M-31 | AG33: J | AH33: V | AI33: S | AJ33: D | AK33: L | AL33: M
F37: LIC. SANDRA CASTILLO HERNÁNDEZ | AA37: MTRA. AIDEE CASTILLO SANDOVAL
F39: JEFE DE ENFERMERAS | AA39: SUBJEFE DE ENFERMERAS

Sheet V-S
A1: INSTITUTO MEXICANO DEL SEGURO SOCIAL
A2: DIRECCION DE PRESTACIONES MEDICAS COORDINACION DE ATENCION INTREGRAL EN SEGUNDO NIVEL
A3: DEPARTAMENTO DE ENFERMERIA
A4: HOSPITAL GENERAL REGIONAL N0. 200
A5: TECAMAC
A7: NOMBRE: | B7: =VLOOKUP(V7,'PLANTILLA VESP'!A1:L298,3,FALSE) -> DE LA PEÑA/HERNANDEZ/BRYAN NEFTALI | J7: CAT: | L7: =VLOOKUP(V7,'PLANTILLA VESP'!A1:L298,4,FALSE) -> AUX DE ENFERMERIA GRAL 80 | S7: MATRICULA: | V7: 97156925 | Y7: CC | AB7: DESCANSO: | AE7: V-S | AH7: No PLAZA | AK7: =VLOOKUP(V7,'PLANTILLA VESP'!A1:L298,2,FALSE) -> 38739
A9: PISO | D9: SERVICIO | J9: F. INGRESO | P9: TIPO DE PLAZA | T9: =VLOOKUP(V7,'PLANTILLA VESP'!A1:L298,11,FALSE) -> CUBRE DESCANSOS BASE | Y9: ROL.VAC | AD9: MARCA DE INC | AJ9: AÑO: 2025
A10: MES/DIA
A11: ENERO | B11: L | C11: M | D11: M-1 | E11: J-2 | F11: V-3 | G11: S-4 | H11: D-5 | I11: L-6 | J11: M-7 | K11: M-8 | L11: J-9 | M11: V-10 | N11: S-11 | O11: D-12 | P11: L-13 | Q11: M-14 | R11: M-15 | S11: J-16 | T11: V-17 | U11: S-18 | V11: D-19 | W11: L-20 | X11: M-21 | Y11: M-22 | Z11: J-23 | AA11: V-24 | AB11: S-25 | AC11: D-26 | AD11: L-27 | AE11: M-28 | AF11: M-29 | AG11: J-30 | AH11: V-31 | AI11: S | AJ11: D | AK11: L | AL11: M
A13: FEBRERO | B13: L | C13: M | D13: M | E13: J | F13: V | G13: S-1 | H13: D-2 | I13: L-3 | J13: M-4 | K13: M-5 | L13: J-6 | M13: V-7 | N13: S-8 | O13: D-9 | P13: L-10 | Q13: M-11 | R13: M-12 | S13: J-13 | T13: V-14 | U13: S-15 | V13: D-16 | W13: L-17 | X13: M-18 | Y13: M-19 | Z13: J-20 | AA13: V-21 | AB13: S-22 | AC13: D-23 | AD13: L-24 | AE13: M-25 | AF13: M-26 | AG13: J-27 | AH13: V- 28 | AI13: S | AJ13: D | AK13: L | AL13: M
A15: MARZO | B15: L | C15: M | D15: M | E15: J | F15: V | G15: S-1 | H15: D-2 | I15: L-3 | J15: M-4 | K15: M-5 | L15: J-6 | M15: V-7 | N15: S-8 | O15: D-9 | P15: L-10 | Q15: M-11 | R15: M-12 | S15: J-13 | T15: V-14 | U15: S-15 | V15: D-16 | W15: L-17 | X15: M-18 | Y15: M-19 | Z15: J-20 | AA15: V-21 | AB15: S-22 | AC15: D-23 | AD15: L-24 | AE15: M-25 | AF15: M-26 | AG15: J-27 | AH15: V- 28 | AI15: S-29 | AJ15: D-30 | AK15: L-31 | AL15: M
A17: ABRIL | B17: L | C17: M-1 | D17: M-2 | E17: J-3 | F17: V-4 | G17: S-5 | H17: D-6 | I17: L-7 | J17: M-8 | K17: M-9 | L17: J-10 | M17: V-11 | N17: S-12 | O17: D-13 | P17: L-14 | Q17: M-15 | R17: M-16 | S17: J-17 | T17: V-18 | U17: S-19 | V17: D-20 | W17: L-21 | X17: M-22 | Y17: M-23 | Z17: J-24 | AA17: V-25 | AB17: S-26 | AC17: D-27 | AD17: L-28 | AE17: M-29 | AF17: M-30 | AG17: J | AH17: V | AI17: S | AJ17: D | AK17: L | AL17: M
A19: MAYO | B19: | | C19: M | D19: M | E19: J-1 | F19: V-2 | G19: S-3 | H19: D-4 | I19: L-5 | J19: M-6 | K19: M-7 | L19: J-8 | M19: V-9 | N19: S-10 | O19: D-11 | P19: L-12 | Q19: M-13 | R19: M-14 | S19: J-15 | T19: V-16 | U19: S-17 | V19: D-18 | W19: L-19 | X19: M-20 | Y19: M-21 | Z19: J-22 | AA19: V-23 | AB19: S-24 | AC19: D-25 | AD19: L-26 | AE19: M-27 | AF19: M-28 | AG19: J-29 | AH19: V-30 | AI19: S-31 | AJ19: D | AK19: L | AL19: M
A21: JUNIO | B21: L | C21: M | D21: M | E21: J | F21: V | G21: S | H21: D-1 | I21: L-2 | J21: M-3 | K21: M-4 | L21: J-5 | M21: V-6 | N21: S-7 | O21: D-8 | P21: L-9 | Q21: M-10 | R21: M-11 | S21: J-12 | T21: V-13 | U21: S-14 | V21: D-15 | W21: L-16 | X21: M-17 | Y21: M-18 | Z21: J-19 | AA21: V-20 | AB21: S-21 | AC21: D-22 | AD21: L-23 | AE21: M-24 | AF21: M-25 | AG21: J-26 | AH21: V- 27 | AI21: S-28 | AJ21: D-29 | AK21: L-30 | AL21: M
